<mujoco model="acroCart">
  <include file="./common/skybox.xml"/>
  <include file="./common/visual.xml"/>
  <include file="./common/materials.xml"/>

  <size njmax="50" nconmax="10" nstack="200"/>

  <option timestep="0.005" iterations="50" solver="Newton" tolerance="1e-10" integrator="RK4">
    <flag contact="disable" energy="enable" frictionloss="disable"/>
  </option>

  <default>
    <muscle ctrllimited="true" ctrlrange="0 1"/>
    <joint type="hinge" pos="0 0 0" axis="0 0 1" limited="false" damping="0"/>
  </default>
  <equality>
		<weld body1="mocap1" body2="cart" solimp="0.02 0.1 0.05" solref="0.06 1"></weld>
	</equality>

  <worldbody>
    <light name="light" pos="0 0 10"/>
    <camera name="fixed" pos="0 -4 1" zaxis="0 -1 0"/>
    <camera name="lookatcart" mode="targetbody" target="cart" pos="0 -2 2"/>
    <geom name="floor" pos="0 0 -.05" size="6 6 .2" type="plane" material="grid"/>
    <site name="s0" pos="0 0.2 4" size="0.02"/>
    <site name="s2" pos="-4 0 4" size="0.02"/>
    <geom name="rail1" type="capsule" pos="0  .2 4" zaxis="1 0 0" size="0.02 4" material="decoration" />
    <geom name="rail2" type="capsule" pos="0 -.2 4" zaxis="1 0 0" size="0.02 4" material="decoration" />
    <body name="mocap1" mocap="true" pos="0 0 8">
      <geom name="mocap" type="sphere" size="0.1" pos="0 0 0"/>
    </body>
    <body name="cart" pos="0 0 4">
      <joint name="slider" type="slide" limited="true" axis="1 0 0" range="-3.8 3.8" solreflimit="0 1" damping="0"/>
      <geom name="cart" type="box" size="0.2 0.4 0.1" material="self"  mass="2"/>
      <site name="s1" pos="0 0 0" size="0.02"/>
      <body name="upper_arm" pos="0 0 0">
        <joint name="shoulder" type="hinge" axis="0 1 0"/>
        <geom name="upper_arm_decoration" material="decoration" type="cylinder" fromto="0 -.06 0 0 .06 0" size="0.051" mass="0"/>
        <geom name="upper_arm" fromto="0 0 0 0 0 2" type="capsule" size="0.05" material="self"/>
        <body name="lower_arm" pos="0 0 2">
          <joint name="elbow" type="hinge" axis="0 1 0"/>
          <geom name="lower_arm" fromto="0 0 0 0 0 1" type="capsule" size="0.049" material="self"/>
          <geom name="mass" material="effector" type="sphere" pos="0 0 1" size="0.1" mass="3"/>
          <site name="tip" pos="0 0 1" size="0.1"/>
        </body>
     </body>
    </body>
  </worldbody>

  <tendon>
    <spatial name="slideIt" width="0.01">
        <site site="s1"/>
        <site site="s2"/>
    </spatial>
  </tendon>

  <actuator>
    <muscle name="slideIt" tendon="slideIt" lengthrange="0 8"/>
  </actuator>

</mujoco>
