<mujoco model="localMotor">

  <include file="./common/visual.xml"/>
  <include file="./common/skybox.xml"/>
  <include file="./common/materials.xml"/>

  <option timestep="0.001" iterations="50" solver="Newton" tolerance="1e-10" cone="elliptic"/>
  <compiler angle="degree"/>

  <asset>
    <texture name="background" builtin="flat" type="2d" mark="random" markrgb="1 1 1" width="800" height="800" rgb1=".2 .3 .4"/>
    <material name="background" texture="background" texrepeat="1 1" texuniform="true"/>
    <texture type="skybox" builtin="gradient" rgb1="0.6 0.6 0.6" rgb2="0 0 0" width="512" height="512"/> 
    <texture name="texplane" type="2d" builtin="checker" rgb1=".25 .25 .25" rgb2=".3 .3 .3" width="512" height="512" mark="cross" markrgb=".8 .8 .8"/>  
    <material name="matplane" reflectance="0.3" texture="texplane" texrepeat="1 1" texuniform="true"/>
  </asset>

  <visual>
    <map shadowclip=".5"/>
    <quality shadowsize="2048"/>
    <rgba haze=".3 .3 .3 1"/>
    <global offheight='1000' offwidth='1000'/>
  </visual>>

  <default>
    <geom friction="0" solimp="0.9 0.97 0.001" solref=".01 1"/>
    <!-- <joint solimplimit="0 0.99 0.01" solreflimit=".005 1"/> -->
    <general ctrllimited="true"/>

    <default class="object">
      <geom material="self"/>
    </default>
    
    <default class="obstacle">
      <geom material="decoration" friction="0"/>
    </default>

    <joint type="hinge" pos="0 0 0" axis="0 1 0" limited="false" range="0 120" damping="0.1"/>
    <muscle ctrllimited="true" ctrlrange="0 180"/>
  </default>

    
    <!-- tendons/muscles -->
    <tendon>
        <spatial name="SF" width="0.01">
            <site site="s0"/>
            <geom geom="shoulder"/>
            <site site="s1"/>
        </spatial>

        <spatial name="SE" width="0.01">
            <site site="s0"/>
            <geom geom="shoulder" sidesite="x0"/>
            <site site="s2"/>
        </spatial>

        <spatial name="EF" width="0.01">
            <site site="s3"/>
            <geom geom="elbow"/>
            <site site="s7"/>
        </spatial>

        <spatial name="EE" width="0.01">
            <site site="s4"/>
            <geom geom="elbow" sidesite="x1"/>
            <site site="s8"/>
        </spatial>

        <spatial name="BF" width="0.009" rgba=".4 .6 .4 1">
            <site site="s0"/>
            <geom geom="shoulder"/>
            <site site="s5"/>
            <geom geom="elbow"/>
            <site site="s7"/>
        </spatial>

        <spatial name="BE" width="0.009" rgba=".4 .6 .4 1">
            <site site="s0"/>
            <geom geom="shoulder" sidesite="x0"/>
            <site site="s6"/>
            <geom geom="elbow" sidesite="x1"/>
            <site site="s8"/>
        </spatial>
    </tendon>   

    <actuator>
        <muscle name="SF" tendon="SF"/>
        <muscle name="SE" tendon="SE"/>
        <muscle name="EF" tendon="EF" />
        <muscle name="EE" tendon="EE"/>
        <muscle name="BF" tendon="BF" />
        <muscle name="BE" tendon="BE"/>
    </actuator>

  <worldbody>
    <!-- Arena -->
    <light name="light" directional="true" diffuse=".6 .6 .6" pos="0 0 1" specular=".3 .3 .3"/>
    <geom name="floor" type="plane" pos="0 0 0" size=".4 .2 10" material="matplane"/>
    <geom name="wall1" type="plane" pos="-.682843 0 .282843" size=".4 .2 10" material="matplane" zaxis="1 0 1"/>
    <geom name="wall2" type="plane" pos=".2 0 .282843" size=".4 .2 10" material="matplane" zaxis="-1 0 1"/>
    <geom name="background" type="plane" pos="0 .2 .5" size="1 .5 10"  material="background" zaxis="0 -1 0"/>    
    <camera name="fixed" pos="-0.1 -2 .5" xyaxes="1 0 0 0 0 1"/>

    <!-- Arm -->    
    <site name="s0" pos="-0.15 0 1" size="0.02"/>
    <site name="x0" pos="0.15 0 1" size="0.02" rgba="0 .7 0 1" group="1"/>

    <body pos="0 0 1" euler="0 90 0">
        <geom name="upper arm" type="capsule" size="0.045" fromto="0 0 0  0.5 0 0" rgba=".5 .1 .1 1"/>
        <joint name="shoulder"  limited="true" range="-30 120"/>
        <geom name="shoulder" type="cylinder" pos="0 0 0" size=".1 .05" euler="90 0 0" rgba=".5 .1 .8 .5" mass="0" group="1"/>

        <site name="s1" pos="0.15 0 -0.06" size="0.02"/>
        <site name="s2" pos="0.15 0 0.06" size="0.02"/>
        <site name="s3" pos="0.4 0 -0.06" size="0.02"/>
        <site name="s4" pos="0.4 0 0.06" size="0.02"/>
        <site name="s5" pos="0.25 0 -0.1" size="0.02"/>
        <site name="s6" pos="0.25 0 0.1" size="0.02"/>
        <site name="x1" pos="0.5 0 0.15" size="0.02" rgba="0 .7 0 1" group="1"/>

        <body pos="0.5 0 0">
            <geom name="forearm" type="capsule" size="0.035" fromto="0 0 0  0.45 0 0" rgba=".5 .1 .1 1"/>
            <joint name="elbow"  limited="true" range="0 120"/>
            <geom name="elbow" type="cylinder" euler="90 0 0" pos="0 0 0" size=".08 .05" rgba=".5 .1 .8 .5" mass="0" group="1"/>

            <site name="s7" pos="0.11 0 -0.05" size="0.02"/>
            <site name="s8" pos="0.11 0 0.05" size="0.02"/>
            
            <geom name="stub" type="cylinder" euler="90 0 0" pos="0.43 0 0" size=".05 .05" rgba=".5 .1 .8 .5" mass="0" group="1"/>
        </body>
    </body>

    <!-- props -->
    <body name="ball1" pos="-1 0 3">
      <joint name="ball1_x" type="slide" axis="1 0 0"/>
      <joint name="ball1_z" type="slide" axis="0 0 1"/>
      <joint name="ball1_y" type="hinge" axis="0 1 0"/>
      <geom name="ball1" type="sphere" size="0.18" material="matplane" rgba="1 1 0 1" mass="1"/>
      <site name="ball1" size=".005"/>
    </body>

    <body name="ball2" pos="-1 0 1.2">
      <joint name="ball2_x" type="slide" axis="1 0 0"/>
      <joint name="ball2_z" type="slide" axis="0 0 1"/>
      <joint name="ball2_y" type="hinge" axis="0 1 0"/>
      <geom name="ball2" type="sphere" size=".1" material="matplane" rgba="1 0 1 1"/>
      <site name="ball2" size=".005"/>
    </body>

    <body name="ball3" pos="-1 0 1.5">
      <joint name="ball3_x" type="slide" axis="1 0 0"/>
      <joint name="ball3_z" type="slide" axis="0 0 1"/>
      <joint name="ball3_y" type="hinge" axis="0 1 0"/>
      <geom name="ball3" type="sphere" size=".05" material="matplane" rgba="0 1 1 1"/>
      <site name="ball3" size=".005"/>
    </body>

    <!-- <body name="box3" pos="-1 0 1.6" childclass="object">
      <joint name="box3_x" type="slide" axis="1 0 0" ref=".2"/>
      <joint name="box3_z" type="slide" axis="0 0 1" ref=".4"/>
      <joint name="box3_y" type="hinge" axis="0 1 0"/>
      <geom  name="box3" type="box" size=".07 .07 .07" />
      <site  name="box3" type="sphere"/>
    </body> -->

  </worldbody>

</mujoco>
